<?xml version="1.0"?>
<robot xmlns:xacro="http://www.ros.org/wiki/xacro" name="turtlebot">
  <!-- Load hardware parameters from the global YAML -->
  <xacro:property name="params_file" value="$(find roboteq_driver)/config/params.yaml"/>
  <xacro:property name="hw_params" value="${xacro.load_yaml(params_file)['hardware_interface']}"/>

  <!-- Minimal robot base link -->
  <link name="base_link"/>

  <!-- Left wheel joint -->
  <joint name="${hw_params['left_joint_name']}" type="continuous">
    <parent link="base_link"/>
    <child link="left_wheel"/>
    <axis xyz="0 0 1"/>
  </joint>
  <link name="left_wheel"/>

  <!-- Right wheel joint -->
  <joint name="${hw_params['right_joint_name']}" type="continuous">
    <parent link="base_link"/>
    <child link="right_wheel"/>
    <axis xyz="0 0 1"/>
  </joint>
  <link name="right_wheel"/>

  <!-- ros2_control integration -->
  <ros2_control name="RoboteqSystem" type="system">
    <hardware>
      <plugin>roboteq_driver/HardwareInterface</plugin>
      <param name="wheel_radius">${hw_params['wheel_radius']}</param>
      <param name="wheel_base">${hw_params['wheel_base']}</param>
      <param name="gear_ratio">${hw_params['gear_ratio']}</param>
      <param name="ticks_per_rev">${hw_params['ticks_per_rev']}</param>
      <param name="left_joint_name">${hw_params['left_joint_name']}</param>
      <param name="right_joint_name">${hw_params['right_joint_name']}</param>
      <param name="feedback_topic">${hw_params['feedback_topic']}</param>
      <param name="cmd_topic">${hw_params['cmd_topic']}</param>
    </hardware>
    <joint name="${hw_params['left_joint_name']}">
      <command_interface name="velocity"/>
      <state_interface name="position"/>
      <state_interface name="velocity"/>
    </joint>
    <joint name="${hw_params['right_joint_name']}">
      <command_interface name="velocity"/>
      <state_interface name="position"/>
      <state_interface name="velocity"/>
    </joint>
  </ros2_control>
</robot>
